<?xml version="1.0"?>
<robot xmlns:xacro="http://wiki.ros.org/xacro">

  <xacro:macro name="aubo_robot" params="
    name
    aubo_type
    tf_prefix
    parent
    *origin
    generate_ros2_control_tag:=true
    transmission_hw_interface:=hardware_interface/PositionJointInterface
    use_fake_hardware:=false
    fake_sensor_commands:=false
    sim_gazebo:=false
    sim_ignition:=false
    rtu_device_name:=/dev/ttyUSB0,115200,N,8,1
    initial_positions:=${dict(shoulder_joint=0.0,upperArm_joint=-0.26179,foreArm_joint=1.74532,wrist1_joint=0.436,wrist2_joint=1.57,wrist3_joint=0.0)}
    robot_ip:=127.0.0.1"
    >

    <xacro:if value="${generate_ros2_control_tag}">
      <!-- ros2 control include -->
      <xacro:include filename="$(find aubo_description)/urdf/aubo.ros2_control.xacro" />
      <!-- ros2 control instance -->
      <xacro:aubo_ros2_control
        name="${name}"
        use_fake_hardware="${use_fake_hardware}"
        initial_positions="${initial_positions}"
        fake_sensor_commands="${fake_sensor_commands}"
        sim_gazebo="${sim_gazebo}"
        sim_ignition="${sim_ignition}"
        tf_prefix="${tf_prefix}"
        robot_ip="${robot_ip}"
        rtu_device_name="${rtu_device_name}"
        />
    </xacro:if>
  
  <!--  aubo urdf file --> 
  <link name="${tf_prefix}aubo_base">
    <inertial>
      <origin xyz="2.1698E-06 0.00017917 0.036984" rpy="0 1.5708 0" />
      <mass value="0.97332" />
      <inertia ixx="0.0015063" ixy="0" ixz="0" iyy="0.0014907" iyz="0" izz="0.0019063" />
    </inertial>
    <visual>
      <origin xyz="0 0 0" rpy="0 0 0" />
      <geometry>
        <mesh filename="package://aubo_description/meshes/${aubo_type}/visual/link0.DAE" />
      </geometry>
      <material name="">
        <color rgba="0.29804 0.29804 0.29804 1" />
      </material>
    </visual>
    <collision>
      <origin xyz="0 0 0" rpy="0 0 0" />
      <geometry>
        <mesh filename="package://aubo_description/meshes/${aubo_type}/collision/link0.STL" />
      </geometry>
    </collision>
  </link>

  <link name="${tf_prefix}shoulder_Link">
    <inertial>
      <origin xyz="-2.9523E-07 0.0037104 -0.0023315" rpy="0 0 0" />
      <mass value="1.173" />  0.0977499609 0.0268634378553496 0.0108 0.016 0.1267
      <inertia ixx="0.0026259" ixy="0" ixz="0" iyy="0.0025333" iyz="0" izz="0.0016014" />
    </inertial>
    <visual>
      <origin xyz="0 0 0" rpy="0 0 0" />
      <geometry>
        <mesh filename="package://aubo_description/meshes/${aubo_type}/visual/link1.DAE" />
      </geometry>
      <material name="">
        <color rgba="0.29804 0.29804 0.29804 1" />
      </material>
    </visual>
    <collision>
      <origin xyz="0 0 0" rpy="0 0 0" />
      <geometry>
        <mesh filename="package://aubo_description/meshes/${aubo_type}/collision/link1.STL" />
      </geometry>
    </collision>
  </link>

  <joint name="${tf_prefix}shoulder_joint" type="revolute">
    <origin xyz="0 0 0.181" rpy="0 0 3.1415926535897932384626433832795" />
    <parent link="${tf_prefix}aubo_base" />
    <child link="${tf_prefix}shoulder_Link" />
    <axis xyz="0 0 1" />
    <limit lower="-3.054326190990076759616458844855" upper="3.054326190990076759616458844855" effort="61" start_stop="102" velocity="3.1104877758314784539234092903757" />
  </joint>

  <link name="${tf_prefix}upperArm_Link">
    <inertial>
      <origin xyz="0.1186 1.7713E-06 0.0063972" rpy="0 0 0" />
      <mass value="2.7791" />
      <inertia ixx="0.0046752" ixy="0" ixz="0.00015757" iyy="0.040156" iyz="0" izz="0.038401" />
    </inertial>
    <visual>
      <origin xyz="0 0 0" rpy="0 0 0" />
      <geometry>
        <mesh filename="package://aubo_description/meshes/${aubo_type}/visual/link2.DAE" />
      </geometry>
      <material name="">
        <color rgba="0.29804 0.29804 0.29804 1" />
      </material>
    </visual>
    <collision>
      <origin xyz="0 0 0" rpy="0 0 0" />
      <geometry>
        <mesh filename="package://aubo_description/meshes/${aubo_type}/collision/link2.STL" />
      </geometry>
    </collision>
  </link>

  <joint name="${tf_prefix}upperArm_joint" type="revolute">
    <origin xyz="0 0.119 0" rpy="-1.5707963267948966192313216916398 -1.5707963267948966192313216916398 0" />
    <parent link="${tf_prefix}shoulder_Link" />
    <child link="${tf_prefix}upperArm_Link" />
    <axis xyz="0 0 1" />
    <limit lower="-3.054326190990076759616458844855" upper="3.054326190990076759616458844855" effort="61" start_stop="102" velocity="3.1104877758314784539234092903757" />
  </joint>

  <link name="${tf_prefix}foreArm_Link">
    <inertial>
      <origin xyz="0.15095 3.6355E-05 0.1001" rpy="0 0 0" />
      <mass value="1.5214" />
      <inertia ixx="0.0014873" ixy="0" ixz="-0.00055006" iyy="0.016144" iyz="0" izz="0.015711" />
    </inertial>
    <visual>
      <origin xyz="0 0 0" rpy="0 0 0" />
      <geometry>
        <mesh filename="package://aubo_description/meshes/${aubo_type}/visual/link3.DAE" />
      </geometry>
      <material name="">
        <color rgba="0.77647 0.75686 0.73725 1" />
      </material>
    </visual>
    <collision>
      <origin xyz="0 0 0" rpy="0 0 0" />
      <geometry>
        <mesh filename="package://aubo_description/meshes/${aubo_type}/collision/link3.STL" />
      </geometry>
    </collision>
  </link>

  <joint name="${tf_prefix}foreArm_joint" type="revolute">
    <origin xyz="0.266 0 0" rpy="-3.1415926535897932384626433832795 0 0" />
    <parent link="${tf_prefix}upperArm_Link" />
    <child link="${tf_prefix}foreArm_Link" />
    <axis xyz="0 0 1" />
    <limit lower="-3.054326190990076759616458844855" upper="3.054326190990076759616458844855" effort="49" start_stop="66" velocity="3.1104877758314784539234092903757" />
  </joint>

  <link name="${tf_prefix}wrist1_Link">
    <inertial>
      <origin xyz="-7.0582E-05 -0.0015345 -0.0029597" rpy="0 0 0" />
      <mass value="0.63348" />
      <inertia ixx="0.0009362" ixy="0" ixz="0" iyy="0.00051333" iyz="0" izz="0.00090515" />
    </inertial>
    <visual>
      <origin xyz="0 0 0" rpy="0 0 0" />
      <geometry>
        <mesh filename="package://aubo_description/meshes/${aubo_type}/visual/link4.DAE" />
      </geometry>
      <material name="">
        <color rgba="0.79216 0.81961 0.93333 1" />
      </material>
    </visual>
    <collision>
      <origin xyz="0 0 0" rpy="0 0 0" />
      <geometry>
        <mesh filename="package://aubo_description/meshes/${aubo_type}/collision/link4.STL" />
      </geometry>
    </collision>
  </link>

  <joint name="${tf_prefix}wrist1_joint" type="revolute">
    <origin xyz="0.2565 0 0" rpy="3.1415926535897932384626433832795 0 1.5707963267948966192313216916398" />
    <parent link="${tf_prefix}foreArm_Link" />
    <child link="${tf_prefix}wrist1_Link" />
    <axis xyz="0 0 1" />
    <limit lower="-3.054326190990076759616458844855" upper="3.054326190990076759616458844855" effort="13.5" start_stop="34" velocity="3.1104877758314784539234092903757" />
  </joint>

  <link name="${tf_prefix}wrist2_Link">
    <inertial>
      <origin xyz="0.0 0.0015345 -0.0029597" rpy="0 0 0" />
      <mass value="0.63348" />
      <inertia ixx="0.0009362" ixy="0" ixz="0" iyy="0.00051333" iyz="7.4602E-06" izz="0.00090515" />
    </inertial>
    <visual>
      <origin xyz="0 0 0" rpy="0 0 0" />
      <geometry>
        <mesh filename="package://aubo_description/meshes/${aubo_type}/visual/link5.DAE" />
      </geometry>
      <material name="">
        <color rgba="0.79216 0.81961 0.93333 1" />
      </material>
    </visual>
    <collision>
      <origin xyz="0 0 0" rpy="0 0 0" />
      <geometry>
        <mesh filename="package://aubo_description/meshes/${aubo_type}/collision/link5.STL" />
      </geometry>
    </collision>
  </link>

  <joint name="${tf_prefix}wrist2_joint" type="revolute">
    <origin xyz="0 0.1025 0" rpy="-1.5707963267948966192313216916398 0 0" />
    <parent link="${tf_prefix}wrist1_Link" />
    <child  link="${tf_prefix}wrist2_Link" />
    <axis xyz="0 0 1" />
    <limit lower="-3.054326190990076759616458844855" upper="3.054326190990076759616458844855" effort="13.5" start_stop="34" velocity="3.1104877758314784539234092903757" />
  </joint>

  <link name="${tf_prefix}wrist3_Link">
    <inertial>
      <origin xyz="8.8789E-10 0.00040506 -0.01865" rpy="0 0 0" />
      <mass value="0.13713" />
      <inertia ixx="6.1911E-05" ixy="0"  ixz="0" iyy="5.9471E-05" iyz="2.8126E-07" izz="9.7957E-05" />
    </inertial>
    <visual>
      <origin xyz="0 0 0" rpy="0 0 0" />
      <geometry>
        <mesh filename="package://aubo_description/meshes/${aubo_type}/visual/link6.DAE" />
      </geometry>
      <material name="">
        <color rgba="0.25098 0.25098 0.25098 1" />
      </material>
    </visual>
    <collision>
      <origin  xyz="0 0 0" rpy="0 0 0" />
      <geometry>
        <mesh filename="package://aubo_description/meshes/${aubo_type}/collision/link6.STL" />
      </geometry>
    </collision>
  </link>

  <joint name="${tf_prefix}wrist3_joint" type="revolute">
    <origin xyz="0 -0.094 0" rpy="1.5707963267948966192313216916398 0 0" />
    <parent link="${tf_prefix}wrist2_Link" />
    <child link="${tf_prefix}wrist3_Link" />
    <axis xyz="0 0 1" />
    <limit lower="-3.054326190990076759616458844855" upper="3.054326190990076759616458844855" effort="13.5" start_stop="34" velocity="3.1104877758314784539234092903757" />
  </joint>

<!-- base_joint fixes aubo_base to the environment -->
    <joint name="${tf_prefix}base_joint" type="fixed">
      <xacro:insert_block name="origin" />
      <parent link="${parent}" />
      <child link="${tf_prefix}aubo_base" />
    </joint>
<!-- ROS-Industrial 'base' frame - aubo_base to AUBO 'Base' Coordinates transform -->
    <link name="${tf_prefix}base"/>
    <joint name="${tf_prefix}aubo_base_fixed_joint" type="fixed">
      <!-- Note the rotation over Z of pi radians - as aubo_base is REP-103
           aligned (i.e., has X+ forward, Y+ left and Z+ up), this is needed
           to correctly align 'base' with the 'Base' coordinate system of
           the UR controller.
      -->
      <origin xyz="0 0 0" rpy="0 0 ${pi}"/>
      <parent link="${tf_prefix}aubo_base"/>
      <child link="${tf_prefix}base"/>
    </joint>

    <!-- ROS-Industrial 'flange' frame - attachment point for EEF models -->
    <link name="${tf_prefix}flange" />
    <joint name="${tf_prefix}wrist3-flange" type="fixed">
      <parent link="${tf_prefix}wrist3_Link" />
      <child link="${tf_prefix}flange" />
      <origin xyz="0 0 0.005" rpy="0 0 0" />
    </joint>

    <!-- ROS-Industrial 'tool0' frame - all-zeros tool frame -->
    <link name="${tf_prefix}tool0">
        <inertial>
      <origin xyz="0 0 -0.155" rpy="${pi/2.0} 0 0" />
      <mass value="0.078562" />
      <inertia ixx="0" ixy="0" ixz="0" iyy="0" iyz="0" izz="0" />
    </inertial>
    <visual>
      <origin xyz="0 0 -0.155" rpy="${pi/2.0} 0 0" />
      <geometry>
        <mesh filename="package://aubo_description/meshes/thirdparts/EG2-4BX.STL" />
      </geometry>
      <material name="">
        <color rgba="1 1 1 1" />
      </material>
    </visual>
    <collision>
      <origin  xyz="0 0 -0.155" rpy="${pi/2.0} 0 0" />
      <geometry>
        <mesh filename="package://aubo_description/meshes/thirdparts/EG2-4BX.STL" />
      </geometry>
    </collision>
    </link>
    <joint name="${tf_prefix}flange-tool0" type="fixed">
      <!-- default toolframe - X+ left, Y+ up, Z+ front -->
      <origin xyz="0 0 0.155" rpy="0 0 0"/>
      <parent link="${tf_prefix}flange"/>
      <child link="${tf_prefix}tool0"/>
    </joint>

  </xacro:macro>
</robot>
