<?xml version="1.0" ?>
<!-- =================================================================================== -->
<!-- |    This document was autogenerated by xacro from aubo.urdf.xacro                | -->
<!-- |    EDITING THIS FILE BY HAND IS NOT RECOMMENDED                                 | -->
<!-- =================================================================================== -->
<robot name="aubo">
  <!-- create link fixed to the "world" -->
  <link name="world"/>
  <ros2_control name="aubo" type="system">
    <hardware>
      <!-- physical hardware or ARCS aubo_scope simulation -->
      <plugin>mock_components/GenericSystem</plugin>
      <param name="fake_sensor_commands">false</param>
      <param name="state_following_offset">0.0</param>
      <!-- <plugin>aubo_hardware/AuboHardwareInterface</plugin>
      <param name="robot_ip">127.0.0.1</param>
      <param name="tf_prefix"></param>
      <param name="rtu_device_name">/dev/ttyUSB0,115200,N,8,1</param> -->
    </hardware>
    <joint name="shoulder_joint">
      <command_interface name="position"/>
      <param name="min">-3.05</param>
      <param name="max">3.05</param>
      <command_interface name="velocity"/>
      <state_interface name="position">
        <param name="initial_value">0</param>
      </state_interface>
      <state_interface name="velocity">
        <param name="initial_value">0.0</param>
      </state_interface>
      <!-- <state_interface name="effort">
                    <param name="initial_value">0.0</param>
                </state_interface> -->
    </joint>
    <joint name="upperArm_joint">
      <command_interface name="position"/>
      <param name="min">-3.05</param>
      <param name="max">3.05</param>
      <command_interface name="velocity"/>
      <state_interface name="position">
        <param name="initial_value">-0.26179938779914946</param>
      </state_interface>
      <state_interface name="velocity">
        <param name="initial_value">0.0</param>
      </state_interface>
      <!-- <state_interface name="effort">
                    <param name="initial_value">0.0</param>
                </state_interface> -->
    </joint>
    <joint name="foreArm_joint">
      <command_interface name="position"/>
      <param name="min">-2.41</param>
      <param name="max">2.41</param>
      <command_interface name="velocity"/>
      <state_interface name="position">
        <param name="initial_value">1.7453292519943295</param>
      </state_interface>
      <state_interface name="velocity">
        <param name="initial_value">0.0</param>
      </state_interface>
      <!-- <state_interface name="effort">
                    <param name="initial_value">0.0</param>
                </state_interface> -->
    </joint>
    <joint name="wrist1_joint">
      <command_interface name="position"/>
      <param name="min">-2.66</param>
      <param name="max">2.66</param>
      <command_interface name="velocity"/>
      <state_interface name="position">
        <param name="initial_value">0.4363323129985824</param>
      </state_interface>
      <state_interface name="velocity">
        <param name="initial_value">0.0</param>
      </state_interface>
      <!-- <state_interface name="effort">
                    <param name="initial_value">0.0</param>
                </state_interface> -->
    </joint>
    <joint name="wrist2_joint">
      <command_interface name="position"/>
      <param name="min">-3.05</param>
      <param name="max">3.05</param>
      <command_interface name="velocity"/>
      <state_interface name="position">
        <param name="initial_value">1.5707963267948966</param>
      </state_interface>
      <state_interface name="velocity">
        <param name="initial_value">0.0</param>
      </state_interface>
      <!-- <state_interface name="effort">
                    <param name="initial_value">0.0</param>
                </state_interface> -->
    </joint>
    <joint name="wrist3_joint">
      <command_interface name="position"/>
      <param name="min">-2.23</param>
      <param name="max">2.23</param>
      <command_interface name="velocity"/>
      <state_interface name="position">
        <param name="initial_value">0</param>
      </state_interface>
      <state_interface name="velocity">
        <param name="initial_value">0.0</param>
      </state_interface>
      <!-- <state_interface name="effort">
                    <param name="initial_value">0.0</param>
                </state_interface> -->
    </joint>
    <gpio name="gpio">
      <command_interface name="standard_digital_output_cmd_0"/>
      <command_interface name="standard_digital_output_cmd_1"/>
      <command_interface name="standard_digital_output_cmd_2"/>
      <command_interface name="standard_digital_output_cmd_3"/>
      <command_interface name="standard_digital_output_cmd_4"/>
      <command_interface name="standard_digital_output_cmd_5"/>
      <command_interface name="standard_digital_output_cmd_6"/>
      <command_interface name="standard_digital_output_cmd_7"/>
      <command_interface name="standard_digital_output_cmd_8"/>
      <command_interface name="standard_digital_output_cmd_9"/>
      <command_interface name="standard_digital_output_cmd_10"/>
      <command_interface name="standard_digital_output_cmd_11"/>
      <command_interface name="standard_analog_output_cmd_0"/>
      <command_interface name="standard_analog_output_cmd_1"/>
      <command_interface name="io_async_success"/>
      <state_interface name="digital_output_0"/>
      <state_interface name="digital_output_1"/>
      <state_interface name="digital_output_2"/>
      <state_interface name="digital_output_3"/>
      <state_interface name="digital_output_4"/>
      <state_interface name="digital_output_5"/>
      <state_interface name="digital_output_6"/>
      <state_interface name="digital_output_7"/>
      <state_interface name="digital_output_8"/>
      <state_interface name="digital_output_9"/>
      <state_interface name="digital_output_10"/>
      <state_interface name="digital_output_11"/>
      <state_interface name="digital_input_0"/>
      <state_interface name="digital_input_1"/>
      <state_interface name="digital_input_2"/>
      <state_interface name="digital_input_3"/>
      <state_interface name="digital_input_4"/>
      <state_interface name="digital_input_5"/>
      <state_interface name="digital_input_6"/>
      <state_interface name="digital_input_7"/>
      <state_interface name="digital_input_8"/>
      <state_interface name="digital_input_9"/>
      <state_interface name="digital_input_10"/>
      <state_interface name="digital_input_11"/>
      <state_interface name="standard_analog_output_0"/>
      <state_interface name="standard_analog_output_1"/>
      <state_interface name="standard_analog_input_0"/>
      <state_interface name="standard_analog_input_1"/>
      <state_interface name="tool_analog_input_0"/>
      <state_interface name="tool_analog_input_1"/>
    </gpio>
    <gpio name="payload">
      <command_interface name="mass"/>
      <command_interface name="cog.x"/>
      <command_interface name="cog.y"/>
      <command_interface name="cog.z"/>
      <command_interface name="payload_async_success"/>
    </gpio>
    <gpio name="system_interface">
      <state_interface name="initialized"/>
    </gpio>
  </ros2_control>
  <!--  aubo urdf file -->
  <link name="aubo_base">
    <inertial>
      <origin rpy="0 0 0" xyz="0.000149 -0.0004 0.0346"/>
      <mass value="1.365846"/>
      <inertia ixx="0.002801" ixy="-0.000001" ixz="0.000002" iyy="0.002763" iyz="0.000011" izz="0.003837"/>
    </inertial>
    <visual>
      <origin rpy="0 0 0" xyz="0 0 0"/>
      <geometry>
        <mesh filename="package://aubo_description/meshes/aubo_C3/visual/link0.DAE"/>
      </geometry>
      <material name="">
        <color rgba="1 1 1 1"/>
      </material>
    </visual>
    <collision>
      <origin rpy="0 0 0" xyz="0 0 0"/>
      <geometry>
        <mesh filename="package://aubo_description/meshes/aubo_C3/collision/link0.STL"/>
      </geometry>
    </collision>
  </link>
  <link name="shoulder_Link">
    <inertial>
      <origin rpy="0 0 0" xyz="-0.000016 0.001852 -0.015716"/>
      <mass value="3.2573"/>
      <inertia ixx="0.005717" ixy="0.000001" ixz="0.000004" iyy="0.005636" iyz="-0.000131" izz="0.003863"/>
    </inertial>
    <visual>
      <origin rpy="0 0 0" xyz="0 0 0"/>
      <geometry>
        <mesh filename="package://aubo_description/meshes/aubo_C3/visual/link1.DAE"/>
      </geometry>
      <material name="">
        <color rgba="1 1 1 1"/>
      </material>
    </visual>
    <collision>
      <origin rpy="0 0 0" xyz="0 0 0"/>
      <geometry>
        <mesh filename="package://aubo_description/meshes/aubo_C3/collision/link1.STL"/>
      </geometry>
    </collision>
  </link>
  <joint name="shoulder_joint" type="revolute">
    <origin rpy="0 0 3.1415926535897932384626433832795" xyz="0 0 0.157"/>
    <parent link="aubo_base"/>
    <child link="shoulder_Link"/>
    <axis xyz="0 0 1"/>
    <limit effort="61" lower="-6.283185307179586476925286766559" start_stop="102" upper="6.283185307179586476925286766559" velocity="3.1104877758314784539234092903757"/>
  </joint>
  <link name="upperArm_Link">
    <inertial>
      <origin rpy="0 0 0" xyz="0.113925 -0.000006 -0.006424"/>
      <mass value="6.116851"/>
      <inertia ixx="0.009999" ixy="0.000018" ixz="-0.000214" iyy="0.106325" iyz="0.000003" izz="0.102883"/>
    </inertial>
    <visual>
      <origin rpy="0 0 0" xyz="0 0 0"/>
      <geometry>
        <mesh filename="package://aubo_description/meshes/aubo_C3/visual/link2.DAE"/>
      </geometry>
      <material name="">
        <color rgba="1 1 1 1"/>
      </material>
    </visual>
    <collision>
      <origin rpy="0 0 0" xyz="0 0 0"/>
      <geometry>
        <mesh filename="package://aubo_description/meshes/aubo_C3/collision/link2.STL"/>
      </geometry>
    </collision>
  </link>
  <joint name="upperArm_joint" type="revolute">
    <origin rpy="-1.5707963267948966192313216916398 -1.5707963267948966192313216916398 0" xyz="0 0.119 0"/>
    <parent link="shoulder_Link"/>
    <child link="upperArm_Link"/>
    <axis xyz="0 0 1"/>
    <limit effort="61" lower="-6.283185307179586476925286766559" start_stop="102" upper="6.283185307179586476925286766559" velocity="3.1104877758314784539234092903757"/>
  </joint>
  <link name="foreArm_Link">
    <inertial>
      <origin rpy="0 0 0" xyz="0.201115 -0.000036 0.093625"/>
      <mass value="2.351523"/>
      <inertia ixx="0.00276" ixy="0.000003" ixz="0.000301" iyy="0.022363" iyz="0.000004" izz="0.021553"/>
    </inertial>
    <visual>
      <origin rpy="0 0 0" xyz="0 0 0"/>
      <geometry>
        <mesh filename="package://aubo_description/meshes/aubo_C3/visual/link3.DAE"/>
      </geometry>
      <material name="">
        <color rgba="1 1 1 1"/>
      </material>
    </visual>
    <collision>
      <origin rpy="0 0 0" xyz="0 0 0"/>
      <geometry>
        <mesh filename="package://aubo_description/meshes/aubo_C3/collision/link3.STL"/>
      </geometry>
    </collision>
  </link>
  <joint name="foreArm_joint" type="revolute">
    <origin rpy="-3.1415926535897932384626433832795 0 0" xyz="0.266 0 0"/>
    <parent link="upperArm_Link"/>
    <child link="foreArm_Link"/>
    <axis xyz="0 0 1"/>
    <limit effort="49" lower="-6.283185307179586476925286766559" start_stop="66" upper="6.283185307179586476925286766559" velocity="3.1104877758314784539234092903757"/>
  </joint>
  <link name="wrist1_Link">
    <inertial>
      <origin rpy="0 0 0" xyz="0.000038 0.011278 -0.001539"/>
      <mass value="1.628022"/>
      <inertia ixx="0.001951" ixy="0.000003" ixz="0.000001" iyy="0.001154" iyz="-0.000042" izz="0.001931"/>
    </inertial>
    <visual>
      <origin rpy="0 0 0" xyz="0 0 0"/>
      <geometry>
        <mesh filename="package://aubo_description/meshes/aubo_C3/visual/link4.DAE"/>
      </geometry>
      <material name="">
        <color rgba="1 1 1 1"/>
      </material>
    </visual>
    <collision>
      <origin rpy="0 0 0" xyz="0 0 0"/>
      <geometry>
        <mesh filename="package://aubo_description/meshes/aubo_C3/collision/link4.STL"/>
      </geometry>
    </collision>
  </link>
  <joint name="wrist1_joint" type="revolute">
    <origin rpy="3.1415926535897932384626433832795 0 1.5707963267948966192313216916398" xyz="0.2565 0 0"/>
    <parent link="foreArm_Link"/>
    <child link="wrist1_Link"/>
    <axis xyz="0 0 1"/>
    <limit effort="13.5" lower="-6.283185307179586476925286766559" start_stop="34" upper="6.283185307179586476925286766559" velocity="3.1104877758314784539234092903757"/>
  </joint>
  <link name="wrist2_Link">
    <inertial>
      <origin rpy="0 0 0" xyz="-0.000038 -0.011278 -0.001539"/>
      <mass value="1.628022"/>
      <inertia ixx="0.001951" ixy="0.000003" ixz="-0.000001" iyy="0.001154" iyz="0.000042" izz="0.001931"/>
    </inertial>
    <visual>
      <origin rpy="0 0 0" xyz="0 0 0"/>
      <geometry>
        <mesh filename="package://aubo_description/meshes/aubo_C3/visual/link5.DAE"/>
      </geometry>
      <material name="">
        <color rgba="1 1 1 1"/>
      </material>
    </visual>
    <collision>
      <origin rpy="0 0 0" xyz="0 0 0"/>
      <geometry>
        <mesh filename="package://aubo_description/meshes/aubo_C3/collision/link5.STL"/>
      </geometry>
    </collision>
  </link>
  <joint name="wrist2_joint" type="revolute">
    <origin rpy="-1.5707963267948966192313216916398 0 0" xyz="0 0.1025 0"/>
    <parent link="wrist1_Link"/>
    <child link="wrist2_Link"/>
    <axis xyz="0 0 1"/>
    <limit effort="13.5" lower="-6.283185307179586476925286766559" start_stop="34" upper="6.283185307179586476925286766559" velocity="3.1104877758314784539234092903757"/>
  </joint>
  <link name="wrist3_Link">
    <inertial>
      <origin rpy="0 0 0" xyz="0.000022 0.0006 -0.017081"/>
      <mass value="0.1978"/>
      <inertia ixx="0.000118" ixy="0" ixz="0" iyy="0.000112" iyz="0.000001" izz="0.000184"/>
    </inertial>
    <visual>
      <origin rpy="0 0 0" xyz="0 0 0"/>
      <geometry>
        <mesh filename="package://aubo_description/meshes/aubo_C3/visual/link6.DAE"/>
      </geometry>
      <material name="">
        <color rgba="1 1 1 1"/>
      </material>
    </visual>
    <collision>
      <origin rpy="0 0 0" xyz="0 0 0"/>
      <geometry>
        <mesh filename="package://aubo_description/meshes/aubo_C3/collision/link6.STL"/>
      </geometry>
    </collision>
  </link>
  <joint name="wrist3_joint" type="revolute">
    <origin rpy="1.5707963267948966192313216916398 0 0" xyz="0 -0.094 0"/>
    <parent link="wrist2_Link"/>
    <child link="wrist3_Link"/>
    <axis xyz="0 0 1"/>
    <limit effort="13.5" lower="-6.283185307179586476925286766559" start_stop="34" upper="6.283185307179586476925286766559" velocity="3.1104877758314784539234092903757"/>
  </joint>
  <!-- base_joint fixes aubo_base to the environment -->
  <joint name="base_joint" type="fixed">
    <origin rpy="0.0 0.0 0.0" xyz="0.0 0.0 0.0"/>
    <parent link="world"/>
    <child link="aubo_base"/>
  </joint>
  <!-- ROS-Industrial 'base' frame - aubo_base to AUBO 'Base' Coordinates transform -->
  <link name="base"/>
  <joint name="aubo_base_fixed_joint" type="fixed">
    <!-- Note the rotation over Z of pi radians - as aubo_base is REP-103
           aligned (i.e., has X+ forward, Y+ left and Z+ up), this is needed
           to correctly align 'base' with the 'Base' coordinate system of
           the UR controller.
      -->
    <origin rpy="0 0 3.141592653589793" xyz="0 0 0"/>
    <parent link="aubo_base"/>
    <child link="base"/>
  </joint>
  <!-- ROS-Industrial 'flange' frame - attachment point for EEF models -->
  <link name="flange"/>
  <joint name="wrist3-flange" type="fixed">
    <parent link="wrist3_Link"/>
    <child link="flange"/>
    <origin rpy="0 -1.5707963267948966 -1.5707963267948966" xyz="0 0 0"/>
  </joint>
  <!-- ROS-Industrial 'tool0' frame - all-zeros tool frame -->
  <link name="tool0"/>
  <joint name="flange-tool0" type="fixed">
    <!-- default toolframe - X+ left, Y+ up, Z+ front -->
    <origin rpy="1.5707963267948966 0 1.5707963267948966" xyz="0 0 0"/>
    <parent link="flange"/>
    <child link="tool0"/>
  </joint>
</robot>
